<?xml version="1.0" encoding="utf-8"?>
<!-- This URDF was automatically created by SolidWorks to URDF Exporter! Originally created by Stephen Brawner (brawner@gmail.com) 
     Commit Version: 1.6.0-1-g15f4949  Build Version: 1.6.7594.29634
     For more information, please see http://wiki.ros.org/sw_urdf_exporter -->
<robot
  name="Arm_Final_Planet_hook">
  <link
    name="base_link">
    <inertial>
      <origin
        xyz="0.0239862312973585 -0.0239843062662296 0.0273877677030368"
        rpy="0 0 0" />
      <mass
        value="0.209863707536" />
      <inertia
        ixx="0.000201299817757715"
        ixy="2.58045330925731E-05"
        ixz="5.59736469617358E-07"
        iyy="0.000201276668092483"
        iyz="-5.59702706110268E-07"
        izz="0.000375387283780294" />
    </inertial>
    <visual>
      <origin
        xyz="0 0 0"
        rpy="0 0 0" />
      <geometry>
        <mesh
          filename="package://Arm_Final_Planet_hook/meshes/base_link.STL" />
      </geometry>
      <material
        name="">
        <color
          rgba="0.792156862745098 0.819607843137255 0.933333333333333 1" />
      </material>
    </visual>
    <collision>
      <origin
        xyz="0 0 0"
        rpy="0 0 0" />
      <geometry>
        <mesh
          filename="package://Arm_Final_Planet_hook/meshes/base_link.STL" />
      </geometry>
    </collision>
  </link>
  <link
    name="link_1">
    <inertial>
      <origin
        xyz="0.000226515984953664 -0.000226515984954184 0.0808458318834426"
        rpy="0 0 0" />
      <mass
        value="0.0467442653932144" />
      <inertia
        ixx="1.55829074302615E-05"
        ixy="-3.03322735015364E-10"
        ixz="-1.25218898458056E-20"
        iyy="3.45644528570318E-05"
        iyz="-8.9999841994293E-21"
        izz="3.90753255796196E-05" />
    </inertial>
    <visual>
      <origin
        xyz="0 0 0"
        rpy="0 0 0" />
      <geometry>
        <mesh
          filename="package://Arm_Final_Planet_hook/meshes/link_1.STL" />
      </geometry>
      <material
        name="">
        <color
          rgba="0.792156862745098 0.819607843137255 0.933333333333333 1" />
      </material>
    </visual>
    <collision>
      <origin
        xyz="0 0 0"
        rpy="0 0 0" />
      <geometry>
        <mesh
          filename="package://Arm_Final_Planet_hook/meshes/link_1.STL" />
      </geometry>
    </collision>
  </link>
  <joint
    name="joint_1"
    type="revolute">
    <origin
      xyz="0 0 0"
      rpy="0 0 0" />
    <parent
      link="base_link" />
    <child
      link="link_1" />
    <axis
      xyz="0 0 1" />
    <limit
      lower="-9000"
      upper="9000"
      effort="0"
      velocity="0" />
    <dynamics
      damping="0"
      friction="0" />
  </joint>
  <link
    name="link_2">
    <inertial>
      <origin
        xyz="0.127388632386799 -1.84215886989136E-09 0.00236974202190602"
        rpy="0 0 0" />
      <mass
        value="0.292295046771137" />
      <inertia
        ixx="8.03288176612902E-05"
        ixy="-1.85198693888772E-07"
        ixz="8.26838164853407E-10"
        iyy="0.000301533110653255"
        iyz="-1.25470650914005E-12"
        izz="0.000272457706804751" />
    </inertial>
    <visual>
      <origin
        xyz="0 0 0"
        rpy="0 0 0" />
      <geometry>
        <mesh
          filename="package://Arm_Final_Planet_hook/meshes/link_2.STL" />
      </geometry>
      <material
        name="">
        <color
          rgba="0.956862745098039 0.956862745098039 0.956862745098039 1" />
      </material>
    </visual>
    <collision>
      <origin
        xyz="0 0 0"
        rpy="0 0 0" />
      <geometry>
        <mesh
          filename="package://Arm_Final_Planet_hook/meshes/link_2.STL" />
      </geometry>
    </collision>
  </link>
  <joint
    name="joint_2"
    type="revolute">
    <origin
      xyz="0.000728149715460716 -0.000228149715460702 0.110999999999998"
      rpy="0 -1.5707963267949 0" />
    <parent
      link="link_1" />
    <child
      link="link_2" />
    <axis
      xyz="0 0 1" />
      <!-- xyz="0 0 -1" /> -->
      
    <limit
      lower="-9000"
      upper="9000"
      effort="0"
      velocity="0" />
    <dynamics
      damping="0"
      friction="0" />
  </joint>
  <link
    name="link_3">
    <inertial>
      <origin
        xyz="0.0911301106082873 -8.27425586380492E-09 -0.00117041616253912"
        rpy="0 0 0" />
      <mass
        value="0.0581573780278174" />
      <inertia
        ixx="5.01081922599441E-05"
        ixy="-1.03721163038904E-12"
        ixz="-6.05693252426838E-10"
        iyy="9.7527219285676E-05"
        iyz="1.25470651700172E-12"
        izz="5.42745376765828E-05" />
    </inertial>
    <visual>
      <origin
        xyz="0 0 0"
        rpy="0 0 0" />
      <geometry>
        <mesh
          filename="package://Arm_Final_Planet_hook/meshes/link_3.STL" />
      </geometry>
      <material
        name="">
        <color
          rgba="0.752941176470588 0.752941176470588 0.752941176470588 1" />
      </material>
    </visual>
    <collision>
      <origin
        xyz="0 0 0"
        rpy="0 0 0" />
      <geometry>
        <mesh
          filename="package://Arm_Final_Planet_hook/meshes/link_3.STL" />
      </geometry>
    </collision>
  </link>
  <joint
    name="joint_3"
    type="revolute">
    <origin
      xyz="0.275000000000002 0 0"
      rpy="0 0 0" />
    <parent
      link="link_2" />
    <child
      link="link_3" />
    <axis
      xyz="0 0 1" />
    <limit
      lower="-9000"
      upper="9000"
      effort="0"
      velocity="0" />
    <dynamics
      damping="0"
      friction="0" />
  </joint>
  <link
    name="hook_link">
    <inertial>
      <origin
        xyz="3.19189119579733E-16 -0.041529054826686 0.0163213132720076"
        rpy="0 0 0" />
      <mass
        value="0.0112613194545346" />
      <inertia
        ixx="2.52073373689584E-05"
        ixy="1.02160648771415E-20"
        ixz="-7.65190904382715E-21"
        iyy="2.03157934535276E-05"
        iyz="7.12371975169594E-07"
        izz="4.98163447106704E-06" />
    </inertial>
    <visual>
      <origin
        xyz="0 0 0"
        rpy="0 0 0" />
      <geometry>
        <mesh
          filename="package://Arm_Final_Planet_hook/meshes/hook_link.STL" />
      </geometry>
      <material
        name="">
        <color
          rgba="0.792156862745098 0.819607843137255 0.933333333333333 1" />
      </material>
    </visual>
    <collision>
      <origin
        xyz="0 0 0"
        rpy="0 0 0" />
      <geometry>
        <mesh
          filename="package://Arm_Final_Planet_hook/meshes/hook_link.STL" />
      </geometry>
    </collision>
  </link>
  <joint
    name="hook_joint"
    type="fixed">
    <origin
      xyz="0.3195 0.0340000000000181 -0.000500000000001256"
      rpy="0 -1.5707963267949 0" />
    <parent
      link="link_3" />
    <child
      link="hook_link" />
    <axis
      xyz="0 -1 0" />
  </joint>
</robot>